Workbook

Sheet Resumo Executivo
B2: Breakeven E-commerce — Dalpack
B5: Resultado atual | E5: Breakeven mensal | H5: Receita necessária em 7 meses
B6: ='Breakeven 7M'!B28 -> -47042.727 | E6: ='Premissas'!F8 -> 70000 | H6: ='Breakeven 7M'!C32 -> 803618.18
B11: Cenário atual x cenário mínimo
B12: Indicador | D12: Atual | F12: Mínimo 7M | H12: Leitura
B13: Faturamento | D13: 214136.28 | F13: 803618.18 | H13: Recupera déficit + custos futuros
B14: Conversão final | D14: 0.016242239 | F14: 0.025196132 | H14: Melhora gradual do funil
B15: Ticket médio | D15: 296.58765 | F15: 307.34516 | H15: Crescimento leve de 1% ao mês
B16: Custo por sessão | D16: 0.79103684 | F16: 0.33727065 | H16: Exige eficiência e tráfego não pago
B17: Resultado líquido | D17: -47042.727 | F17: 0 | H17: Projeto zerado no fim do Mês 7
B20: Evolução financeira
H22: Leitura estratégica O cenário mínimo não depende apenas de mídia. Com verba mensal de R$ 5 mil, o projeto precisa combinar melhora de conversão, recuperação de tracking, CRM/recompra e tráfego orgânico para atingir as sessões necessárias sem pressionar o custo de aquisição.
H29: Status
H30: =IF('Breakeven 7M'!K28>=-0.01,"BREAKEVEN NO MÊS 7","REVISAR CENÁRIO") -> BREAKEVEN NO MÊS 7
B42: Comparativo dos três cenários
B43: Cenário | D43: Receita 7M | F43: Mídia 7M | H43: Saldo final | J43: Mês de breakeven
B44: Pessimista | D44: ='Pessimista'!D6 -> 350000 | F44: ='Pessimista'!D4 -> 35000 | H44: ='Pessimista'!D11 -> -68042.73 | J44: Não breakeva
B45: Realista | D45: ='Realista'!D6 -> 983000 | F45: ='Realista'!D4 -> 59000 | H45: ='Realista'!D11 -> 2907.27 | J45: Mês 7
B46: Otimista | D46: ='Otimista'!D6 -> 1152000 | F46: ='Otimista'!D4 -> 59000 | H46: ='Otimista'!D11 -> 28257.27 | J46: Mês 6

Sheet Breakeven 7M
A1: Projeção Breakeven — Dalpack
A2: Custos Fixos V4 + Mídia | B2: ='Premissas'!B9 -> 79163.169 | C2: =SUM(E2:K2) -> 73500 | E2: =E3+E4 -> 10500 | F2: =F3+F4 -> 10500 | G2: =G3+G4 -> 10500 | H2: =H3+H4 -> 10500 | I2: =I3+I4 -> 10500 | J2: =J3+J4 -> 10500 | K2: =K3+K4 -> 10500
A3: Fee Mensal | B3: ='Premissas'!B7 -> 44000 | C3: =SUM(E3:K3) -> 38500 | E3: ='Premissas'!F4 -> 5500 | F3: ='Premissas'!F4 -> 5500 | G3: ='Premissas'!F4 -> 5500 | H3: ='Premissas'!F4 -> 5500 | I3: ='Premissas'!F4 -> 5500 | J3: ='Premissas'!F4 -> 5500 | K3: ='Premissas'!F4 -> 5500
A4: Verba de mídia | B4: ='Premissas'!B8 -> 35163.169 | C4: =SUM(E4:K4) -> 35000 | E4: ='Premissas'!F5 -> 5000 | F4: ='Premissas'!F5 -> 5000 | G4: ='Premissas'!F5 -> 5000 | H4: ='Premissas'!F5 -> 5000 | I4: ='Premissas'!F5 -> 5000 | J4: ='Premissas'!F5 -> 5000 | K4: ='Premissas'!F5 -> 5000
A5: Sessões por mês | B5: ='Premissas'!B11 -> 44452 | C5: =SUM(E5:K5) -> 103774.23 | E5: =E11/E13 -> 10274.897 | F5: =F11/F13 -> 12310.312 | G5: =G11/G13 -> 14101.264 | H5: =H11/H13 -> 15680.089 | I5: =I11/I13 -> 16331.615 | J5: =J11/J13 -> 17367.712 | K5: =K11/K13 -> 17708.336
A6: Custo por Sessão | B6: =B4/B5 -> 0.79103684 | C6: =C4/C5 -> 0.33727065 | E6: =E4/E5 -> 0.4866229 | F6: =F4/F5 -> 0.40616355 | G6: =G4/G5 -> 0.35457814 | H6: =H4/H5 -> 0.31887575 | I6: =I4/I5 -> 0.30615465 | J6: =J4/J5 -> 0.28789054 | K6: =K4/K5 -> 0.2823529
A7: Taxa de Conversão Sessão → Pedidos | B7: =B8/B5 -> 0.019504184 | C7: =C8/C5 -> 0.029890079 | E7: =E8/E5 -> 0.024273483 | F7: =F8/F5 -> 0.025896741 | G7: =G8/G5 -> 0.027562443 | H7: =H8/H5 -> 0.029270154 | I7: =I8/I5 -> 0.031019445 | J7: =J8/J5 -> 0.03244534 | K7: =K8/K5 -> 0.034779805
A8: Pedidos por mês | B8: ='Premissas'!B12 -> 867 | C8: =SUM(E8:K8) -> 3101.8198 | E8: =E11/E10 -> 249.40753 | F8: =F11/F10 -> 318.79695 | G8: =G11/G10 -> 388.66529 | H8: =H11/H10 -> 458.9586 | I8: =I11/I10 -> 506.59765 | J8: =J11/J10 -> 563.50132 | K8: =K11/K10 -> 615.89247
A9: Custo por Pedido | B9: =B4/B8 -> 40.557289 | C9: =C4/C8 -> 11.283699 | E9: =E4/E8 -> 20.04751 | F9: =F4/F8 -> 15.683964 | G9: =G4/G8 -> 12.86454 | H9: =H4/H8 -> 10.894229 | I9: =I4/I8 -> 9.8697654 | J9: =J4/J8 -> 8.8730936 | K9: =K4/K8 -> 8.1183002
A10: Taxa de Conversão Pedidos → Venda | B10: =B11/B8 -> 0.83275663 | C10: =C11/C8 -> 0.84295969 | E10: ='Premissas'!F18 -> 0.83275663 | F10: ='Premissas'!G18 -> 0.83563053 | G10: ='Premissas'!H18 -> 0.83850442 | H10: ='Premissas'!I18 -> 0.84137832 | I10: ='Premissas'!J18 -> 0.84425221 | J10: ='Premissas'!K18 -> 0.84712611 | K10: ='Premissas'!L18 -> 0.85
A11: Vendas por mês | B11: ='Premissas'!B13 -> 722 | C11: =SUM(E11:K11) -> 2614.7091 | E11: =E18/E15 -> 207.69577 | F11: =F18/F15 -> 266.39647 | G11: =G18/G15 -> 325.89756 | H11: =H18/H15 -> 386.15782 | I11: =I18/I15 -> 427.69619 | J11: =J18/J15 -> 477.35668 | K11: =K18/K15 -> 523.5086
A12: Custo por Venda | B12: =B4/B11 -> 48.702451 | C12: =C4/C11 -> 13.38581 | E12: =E4/E11 -> 24.073673 | F12: =F4/F11 -> 18.769018 | G12: =G4/G11 -> 15.342244 | H12: =H4/H11 -> 12.948074 | I12: =I4/I11 -> 11.690541 | J12: =J4/J11 -> 10.474348 | K12: =K4/K11 -> 9.5509414
A13: Taxa de Conversão do Funil | B13: =B11/B5 -> 0.016242239 | C13: =C11/C5 -> 0.025196132 | E13: ='Premissas'!F15*'Premissas'!F16*'Premissas'!F17 -> 0.020213904 | F13: ='Premissas'!G15*'Premissas'!G16*'Premissas'!G17 -> 0.021640107 | G13: ='Premissas'!H15*'Premissas'!H16*'Premissas'!H17 -> 0.02311123 | H13: ='Premissas'!I15*'Premissas'!I16*'Premissas'!I17 -> 0.024627273 | I13: ='Premissas'!J15*'Premissas'!J16*'Premissas'!J17 -> 0.026188235 | J13: ='Premissas'!K15*'Premissas'!K16*'Premissas'!K17 -> 0.027485294 | K13: ='Premissas'!L15*'Premissas'!L16*'Premissas'!L17 -> 0.029562834
A15: Ticket médio | B15: ='Premissas'!B14 -> 296.58765 | C15: =C18/C11 -> 307.34516 | E15: =B15 -> 296.58765 | F15: =E15*1.01 -> 299.55352 | G15: =F15*1.01 -> 302.54906 | H15: =G15*1.01 -> 305.57455 | I15: =H15*1.01 -> 308.63029 | J15: =I15*1.01 -> 311.7166 | K15: =J15*1.01 -> 314.83376
A16: Margem Contribuição (MC) | B16: ='Premissas'!B15 -> 0.15 | C16: ='Premissas'!F7 -> 0.15 | E16: ='Premissas'!F7 -> 0.15 | F16: ='Premissas'!F7 -> 0.15 | G16: ='Premissas'!F7 -> 0.15 | H16: ='Premissas'!F7 -> 0.15 | I16: ='Premissas'!F7 -> 0.15 | J16: ='Premissas'!F7 -> 0.15 | K16: ='Premissas'!F7 -> 0.15
A18: Valor de Venda no mês | B18: ='Premissas'!B10 -> 214136.28 | C18: =SUM(E18:K18) -> 803618.18 | E18: ='Premissas'!F14 -> 61600 | F18: ='Premissas'!G14 -> 79800 | G18: ='Premissas'!H14 -> 98600 | H18: ='Premissas'!I14 -> 118000 | I18: ='Premissas'!J14 -> 132000 | J18: ='Premissas'!K14 -> 148800 | K18: ='Premissas'!L14 -> 164818.18
A19: Valor Acumulado | B19: =B18 -> 214136.28 | C19: =C18 -> 803618.18 | E19: =SUM($E18:E18) -> 61600 | F19: =SUM($E18:F18) -> 141400 | G19: =SUM($E18:G18) -> 240000 | H19: =SUM($E18:H18) -> 358000 | I19: =SUM($E18:I18) -> 490000 | J19: =SUM($E18:J18) -> 638800 | K19: =SUM($E18:K18) -> 803618.18
A20: ROAS no mês | B20: =B18/B4 -> 6.0897889 | C20: =C18/C4 -> 22.96052 | E20: =E18/E4 -> 12.32 | F20: =F18/F4 -> 15.96 | G20: =G18/G4 -> 19.72 | H20: =H18/H4 -> 23.6 | I20: =I18/I4 -> 26.4 | J20: =J18/J4 -> 29.76 | K20: =K18/K4 -> 32.963637
A21: Resultado MC/mês | B21: =B18*B16 -> 32120.442 | C21: =C18*C16 -> 120542.73 | E21: =E18*E16 -> 9240 | F21: =F18*F16 -> 11970 | G21: =G18*G16 -> 14790 | H21: =H18*H16 -> 17700 | I21: =I18*I16 -> 19800 | J21: =J18*J16 -> 22320 | K21: =K18*K16 -> 24722.727
A22: Resultado MC Acumulado | B22: =B21 -> 32120.442 | C22: =C21 -> 120542.73 | E22: =SUM($E21:E21) -> 9240 | F22: =SUM($E21:F21) -> 21210 | G22: =SUM($E21:G21) -> 36000 | H22: =SUM($E21:H21) -> 53700 | I22: =SUM($E21:I21) -> 73500 | J22: =SUM($E21:J21) -> 95820 | K22: =SUM($E21:K21) -> 120542.73
A24: Custo V4 + mídia/mês | B24: =B2 -> 79163.169 | C24: =C2 -> 73500 | E24: =E2 -> 10500 | F24: =F2 -> 10500 | G24: =G2 -> 10500 | H24: =H2 -> 10500 | I24: =I2 -> 10500 | J24: =J2 -> 10500 | K24: =K2 -> 10500
A25: Custo V4 + mídia acumulado | B25: =B24 -> 79163.169 | C25: =C24 -> 73500 | E25: =SUM($E24:E24) -> 10500 | F25: =SUM($E24:F24) -> 21000 | G25: =SUM($E24:G24) -> 31500 | H25: =SUM($E24:H24) -> 42000 | I25: =SUM($E24:I24) -> 52500 | J25: =SUM($E24:J24) -> 63000 | K25: =SUM($E24:K24) -> 73500
A27: Resultado líquido Mês | B27: =B21-B24 -> -47042.727 | C27: =C21-C24 -> 47042.727 | E27: =E21-E24 -> -1260 | F27: =F21-F24 -> 1470 | G27: =G21-G24 -> 4290 | H27: =H21-H24 -> 7200 | I27: =I21-I24 -> 9300 | J27: =J21-J24 -> 11820 | K27: =K21-K24 -> 14222.727
A28: Resultado líquido Acumulado | B28: =B27 -> -47042.727 | C28: =ROUND(B28+C27,2) -> 0 | E28: =ROUND($B28+SUM($E27:E27),2) -> -48302.73 | F28: =ROUND($B28+SUM($E27:F27),2) -> -46832.73 | G28: =ROUND($B28+SUM($E27:G27),2) -> -42542.73 | H28: =ROUND($B28+SUM($E27:H27),2) -> -35342.73 | I28: =ROUND($B28+SUM($E27:I27),2) -> -26042.73 | J28: =ROUND($B28+SUM($E27:J27),2) -> -14222.73 | K28: =ROUND($B28+SUM($E27:K27),2) -> 0
A29: ROI no mês | B29: =B21/B24 -> 0.40574982 | C29: =C21/C24 -> 1.6400371 | E29: =E21/E24 -> 0.88 | F29: =F21/F24 -> 1.14 | G29: =G21/G24 -> 1.4085714 | H29: =H21/H24 -> 1.6857143 | I29: =I21/I24 -> 1.8857143 | J29: =J21/J24 -> 2.1257143 | K29: =K21/K24 -> 2.3545455
A30: ROI Projeto | B30: =B22/B25 -> 0.40574982 | C30: =(B22+C22)/(B25+C25) -> 1 | E30: =($B22+E22)/($B25+E25) -> 0.46128686 | F30: =($B22+F22)/($B25+F25) -> 0.53243565 | G30: =($B22+G22)/($B25+G25) -> 0.61556562 | H30: =($B22+H22)/($B25+H25) -> 0.7083047 | I30: =($B22+I22)/($B25+I25) -> 0.80220188 | J30: =($B22+J22)/($B25+J25) -> 0.89995491 | K30: =($B22+K22)/($B25+K25) -> 1
A32: Receita futura necessária | B32: ='Premissas'!F10 -> 803618.18 | C32: ='Premissas'!F10 -> 803618.18
A33: Status do breakeven | B33: =IF(B28>=0,"Já breakevado","Déficit a recuperar") -> Déficit a recuperar | C33: =IF(C28>=-0.01,"Breakeven atingido","Revisar premissas") -> Breakeven atingido
A36: Funil completo do cenário mínimo
A37: Sessões | B37: 5307 | C37: =SUM(E37:K37) -> 103774.23 | E37: =E39/E38 -> 10274.897 | F37: =F39/F38 -> 12310.312 | G37: =G39/G38 -> 14101.264 | H37: =H39/H38 -> 15680.089 | I37: =I39/I38 -> 16331.615 | J37: =J39/J38 -> 17367.712 | K37: =K39/K38 -> 17708.336
A38: Taxa Sessão → View item | B38: 0.79574147 | C38: =C39/C37 -> 0.86159062 | E38: 0.8 | F38: 0.82 | G38: 0.84 | H38: 0.86 | I38: 0.88 | J38: 0.89 | K38: 0.9
A39: View item | B39: 4223 | C39: =SUM(E39:K39) -> 89410.899 | E39: =E41/E40 -> 8219.9173 | F39: =F41/F40 -> 10094.456 | G39: =G41/G40 -> 11845.062 | H39: =H41/H40 -> 13484.876 | I39: =I41/I40 -> 14371.822 | J39: =J41/J40 -> 15457.264 | K39: =K41/K40 -> 15937.502
A40: Taxa View item → Add to cart | B40: 0.044281317 | C40: =C41/C39 -> 0.19763998 | E40: 0.2078224 | F40: 0.20572895 | G40: 0.20100218 | H40: 0.19694719 | I40: 0.19342811 | J40: 0.19156793 | K40: 0.19503946
A41: Add to cart | B41: 187 | C41: =SUM(E41:K41) -> 17671.169 | E41: =E43/E42 -> 1708.2829 | F41: =F43/F42 -> 2076.7218 | G41: =G43/G42 -> 2380.8833 | H41: =H43/H42 -> 2655.8085 | I41: =I43/I42 -> 2779.9143 | J41: =J43/J42 -> 2961.116 | K41: =K43/K42 -> 3108.4419
A42: Taxa Add to cart → View cart | B42: 1 | C42: =C43/C41 -> 1 | E42: 1 | F42: 1 | G42: 1 | H42: 1 | I42: 1 | J42: 1 | K42: 1
A43: View cart | B43: 306 | C43: =SUM(E43:K43) -> 17671.169 | E43: =E45/E44 -> 1708.2829 | F43: =F45/F44 -> 2076.7218 | G43: =G45/G44 -> 2380.8833 | H43: =H45/H44 -> 2655.8085 | I43: =I45/I44 -> 2779.9143 | J43: =J45/J44 -> 2961.116 | K43: =K45/K44 -> 3108.4419
A44: Taxa View cart → Begin checkout | B44: 0.72875817 | C44: =C45/C43 -> 0.8984625 | E44: 0.897 | F44: 0.897 | G44: 0.898 | H44: 0.898 | I44: 0.899 | J44: 0.899 | K44: 0.9
A45: Begin checkout | B45: 223 | C45: =SUM(E45:K45) -> 15876.882 | E45: =E47/E46 -> 1532.3298 | F45: =F47/F46 -> 1862.8194 | G45: =G47/G46 -> 2138.0332 | H45: =H47/H46 -> 2384.916 | I45: =I47/I46 -> 2499.143 | J45: =J47/J46 -> 2662.0433 | K45: =K47/K46 -> 2797.5977
A46: Taxa Begin checkout → Add shipping info | B46: 1 | C46: =C47/C45 -> 0.71858639 | E46: 0.6846 | F46: 0.695 | G46: 0.705 | H46: 0.715 | I46: 0.725 | J46: 0.735 | K46: 0.745
A47: Add shipping info | B47: 495 | C47: =SUM(E47:K47) -> 11408.912 | E47: =E49/E48 -> 1049.033 | F47: =F49/F48 -> 1294.6595 | G47: =G49/G48 -> 1507.3134 | H47: =H49/H48 -> 1705.2149 | I47: =I49/I48 -> 1811.8787 | J47: =J49/J48 -> 1956.6018 | K47: =K49/K48 -> 2084.2103
...

Sheet Pessimista
A1: Breakeven Pessimista — Dalpack
B2: Atual acumulado / funil maio | C2: Breakeven da competência | D2: Total projetado | F2: Mês 1 | G2: Mês 2 | H2: Mês 3 | I2: Mês 4 | J2: Mês 5 | K2: Mês 6 | L2: Mês 7
A3: Fee V4 | B3: 44000 | C3: ='Premissas'!F4 -> 5500 | D3: =SUM(F3:L3) -> 38500 | F3: ='Premissas'!F4 -> 5500 | G3: ='Premissas'!F4 -> 5500 | H3: ='Premissas'!F4 -> 5500 | I3: ='Premissas'!F4 -> 5500 | J3: ='Premissas'!F4 -> 5500 | K3: ='Premissas'!F4 -> 5500 | L3: ='Premissas'!F4 -> 5500
A4: Investimento de mídia | B4: 35163.169 | C4: =F4 -> 5000 | D4: =SUM(F4:L4) -> 35000 | F4: 5000 | G4: 5000 | H4: 5000 | I4: 5000 | J4: 5000 | K4: 5000 | L4: 5000
A5: Custo total | B5: 79163.169 | C5: =C3+C4 -> 10500 | D5: =SUM(F5:L5) -> 73500 | F5: =F3+F4 -> 10500 | G5: =G3+G4 -> 10500 | H5: =H3+H4 -> 10500 | I5: =I3+I4 -> 10500 | J5: =J3+J4 -> 10500 | K5: =K3+K4 -> 10500 | L5: =L3+L4 -> 10500
A6: Faturamento | B6: 214136.28 | C6: =C5/C8 -> 70000 | D6: =SUM(F6:L6) -> 350000 | F6: 35000 | G6: 40000 | H6: 45000 | I6: 50000 | J6: 55000 | K6: 60000 | L6: 65000
A7: Ticket médio | B7: 296.58765 | C7: =F7 -> 300 | D7: =D6/D32 -> 306.74977 | F7: 300 | G7: 302 | H7: 304 | I7: 306 | J7: 308 | K7: 310 | L7: 312
A8: Margem de contribuição | B8: 0.15 | C8: ='Premissas'!F7 -> 0.15 | D8: ='Premissas'!F7 -> 0.15 | F8: ='Premissas'!F7 -> 0.15 | G8: ='Premissas'!F7 -> 0.15 | H8: ='Premissas'!F7 -> 0.15 | I8: ='Premissas'!F7 -> 0.15 | J8: ='Premissas'!F7 -> 0.15 | K8: ='Premissas'!F7 -> 0.15 | L8: ='Premissas'!F7 -> 0.15
A9: Resultado MC | B9: 32120.442 | C9: =C6*C8 -> 10500 | D9: =D6*D8 -> 52500 | F9: =F6*F8 -> 5250 | G9: =G6*G8 -> 6000 | H9: =H6*H8 -> 6750 | I9: =I6*I8 -> 7500 | J9: =J6*J8 -> 8250 | K9: =K6*K8 -> 9000 | L9: =L6*L8 -> 9750
A10: Resultado líquido do mês | B10: -47042.727 | C10: =C9-C5 -> 0 | D10: =D9-D5 -> -21000 | F10: =F9-F5 -> -5250 | G10: =G9-G5 -> -4500 | H10: =H9-H5 -> -3750 | I10: =I9-I5 -> -3000 | J10: =J9-J5 -> -2250 | K10: =K9-K5 -> -1500 | L10: =L9-L5 -> -750
A11: Resultado líquido acumulado | B11: -47042.727 | C11: =C10 -> 0 | D11: =L11 -> -68042.73 | F11: =ROUND($B11+F10,2) -> -52292.73 | G11: =ROUND(F11+G10,2) -> -56792.73 | H11: =ROUND(G11+H10,2) -> -60542.73 | I11: =ROUND(H11+I10,2) -> -63542.73 | J11: =ROUND(I11+J10,2) -> -65792.73 | K11: =ROUND(J11+K10,2) -> -67292.73 | L11: =ROUND(K11+L10,2) -> -68042.73
A12: ROAS | B12: 6.0897889 | C12: =C6/C4 -> 14 | D12: =D6/D4 -> 10 | F12: =F6/F4 -> 7 | G12: =G6/G4 -> 8 | H12: =H6/H4 -> 9 | I12: =I6/I4 -> 10 | J12: =J6/J4 -> 11 | K12: =K6/K4 -> 12 | L12: =L6/L4 -> 13
A13: Status | B13: Déficit a recuperar | C13: ZERA A COMPETÊNCIA | D13: =IF(D11>=0,"BREAKEVEN ATINGIDO","NÃO BREAKEVA") -> NÃO BREAKEVA | F13: =IF(F11>=0,"BREAKEVEN","EM RECUPERAÇÃO") -> EM RECUPERAÇÃO | G13: =IF(G11>=0,"BREAKEVEN","EM RECUPERAÇÃO") -> EM RECUPERAÇÃO | H13: =IF(H11>=0,"BREAKEVEN","EM RECUPERAÇÃO") -> EM RECUPERAÇÃO | I13: =IF(I11>=0,"BREAKEVEN","EM RECUPERAÇÃO") -> EM RECUPERAÇÃO | J13: =IF(J11>=0,"BREAKEVEN","EM RECUPERAÇÃO") -> EM RECUPERAÇÃO | K13: =IF(K11>=0,"BREAKEVEN","EM RECUPERAÇÃO") -> EM RECUPERAÇÃO | L13: =IF(L11>=0,"BREAKEVEN","EM RECUPERAÇÃO") -> EM RECUPERAÇÃO
A15: Funil completo mês a mês
A16: Sessões | B16: 5307 | C16: =C18/C17 -> 15728.312 | D16: =SUM(F16:L16) -> 63460.62 | F16: =F18/F17 -> 7864.1559 | G16: =G18/G17 -> 8374.2786 | H16: =H18/H17 -> 8769.4126 | I16: =I18/I17 -> 9077.882 | J16: =J18/J17 -> 9378.2765 | K16: =K18/K17 -> 9805.9708 | L16: =L18/L17 -> 10190.643
A17: Taxa Sessão → View item | B17: 0.79574147 | C17: =F17 -> 0.8 | D17: =D18/D16 -> 0.83164696 | F17: 0.8 | G17: 0.81 | H17: 0.82 | I17: 0.83 | J17: 0.84 | K17: 0.85 | L17: 0.86
A18: View item | B18: 4223 | C18: =C20/C19 -> 12582.649 | D18: =SUM(F18:L18) -> 52776.832 | F18: =F20/F19 -> 6291.3247 | G18: =G20/G19 -> 6783.1657 | H18: =H20/H19 -> 7190.9183 | I18: =I20/I19 -> 7534.6421 | J18: =J20/J19 -> 7877.7523 | K18: =K20/K19 -> 8335.0752 | L18: =L20/L19 -> 8763.9532
A19: Taxa View item → Add to cart | B19: 0.044281317 | C19: =F19 -> 0.21875 | D19: =D20/D18 -> 0.21922419 | F19: 0.21875 | G19: 0.2191358 | H19: 0.2195122 | I19: 0.21987952 | J19: 0.2202381 | K19: 0.21911765 | L19: 0.21802326
A20: Add to cart | B20: 187 | C20: =C22/C21 -> 2752.4546 | D20: =SUM(F20:L20) -> 11569.958 | F20: =F22/F21 -> 1376.2273 | G20: =G22/G21 -> 1486.4345 | H20: =H22/H21 -> 1578.4943 | I20: =I22/I21 -> 1656.7135 | J20: =J22/J21 -> 1734.9812 | K20: =K22/K21 -> 1826.3621 | L20: =L22/L21 -> 1910.7456
A21: Taxa Add to cart → View cart | B21: 1 | C21: =F21 -> 0.8 | D21: =D22/D20 -> 0.8 | F21: 0.8 | G21: 0.8 | H21: 0.8 | I21: 0.8 | J21: 0.8 | K21: 0.8 | L21: 0.8
A22: View cart | B22: 306 | C22: =C24/C23 -> 2201.9637 | D22: =SUM(F22:L22) -> 9255.9666 | F22: =F24/F23 -> 1100.9818 | G22: =G24/G23 -> 1189.1476 | H22: =H24/H23 -> 1262.7954 | I22: =I24/I23 -> 1325.3708 | J22: =J24/J23 -> 1387.9849 | K22: =K24/K23 -> 1461.0896 | L22: =L24/L23 -> 1528.5965
A23: Taxa View cart → Begin checkout | B23: 0.72875817 | C23: =F23 -> 0.75 | D23: =D24/D22 -> 0.77966808 | F23: 0.75 | G23: 0.76 | H23: 0.77 | I23: 0.78 | J23: 0.79 | K23: 0.795 | L23: 0.8
A24: Begin checkout | B24: 223 | C24: =C26/C25 -> 1651.4727 | D24: =SUM(F24:L24) -> 7216.5817 | F24: =F26/F25 -> 825.73637 | G24: =G26/G25 -> 903.75215 | H24: =H26/H25 -> 972.35247 | I24: =I26/I25 -> 1033.7892 | J24: =J26/J25 -> 1096.5081 | K24: =K26/K25 -> 1161.5663 | L24: =L26/L25 -> 1222.8772
A25: Taxa Begin checkout → Add shipping info | B25: 1 | C25: =F25 -> 0.7 | D25: =D26/D24 -> 0.73003817 | F25: 0.7 | G25: 0.71 | H25: 0.72 | I25: 0.73 | J25: 0.74 | K25: 0.745 | L25: 0.75
A26: Add shipping info | B26: 495 | C26: =C28/C27 -> 1156.0309 | D26: =SUM(F26:L26) -> 5268.3801 | F26: =F28/F27 -> 578.01546 | G26: =G28/G27 -> 641.66403 | H26: =H28/H27 -> 700.09378 | I26: =I28/I27 -> 754.66612 | J26: =J28/J27 -> 811.41599 | K26: =K28/K27 -> 865.36687 | L26: =L28/L27 -> 917.1579
A27: Taxa Add shipping info → Add payment info | B27: 0.66060606 | C27: =F27 -> 0.66 | D27: =D28/D26 -> 0.68796777 | F27: 0.66 | G27: 0.67 | H27: 0.68 | I27: 0.69 | J27: 0.695 | K27: 0.7 | L27: 0.705
A28: Add payment info | B28: 327 | C28: =C30/C29 -> 762.98041 | D28: =SUM(F28:L28) -> 3624.4757 | F28: =F30/F29 -> 381.4902 | G28: =G30/G29 -> 429.9149 | H28: =H30/H29 -> 476.06377 | I28: =I30/I29 -> 520.71962 | J28: =J30/J29 -> 563.93411 | K28: =K30/K29 -> 605.75681 | L28: =L30/L29 -> 646.59632
A29: Taxa Add payment info → Pedido | B29: 0.34250765 | C29: =F29 -> 0.3425 | D29: =D30/D28 -> 0.35207474 | F29: 0.3425 | G29: 0.345 | H29: 0.348 | I29: 0.351 | J29: 0.354 | K29: 0.357 | L29: 0.36
A30: Pedidos | B30: 112 | C30: =C32/C31 -> 261.32079 | D30: =SUM(F30:L30) -> 1276.0863 | F30: =F32/F31 -> 130.66039 | G30: =G32/G31 -> 148.32064 | H30: =H32/H31 -> 165.67019 | I30: =I32/I31 -> 182.77259 | J30: =J32/J31 -> 199.63268 | K30: =K32/K31 -> 216.25518 | L30: =L32/L31 -> 232.77467
A31: Taxa Pedido → Venda | B31: 0.89285714 | C31: =F31 -> 0.8929 | D31: =D32/D30 -> 0.89413633 | F31: 0.8929 | G31: 0.893 | H31: 0.8935 | I31: 0.894 | J31: 0.8945 | K31: 0.895 | L31: 0.895
A32: Vendas | B32: 100 | C32: =C6/C7 -> 233.33333 | D32: =SUM(F32:L32) -> 1140.9952 | F32: =F6/F7 -> 116.66667 | G32: =G6/G7 -> 132.45033 | H32: =H6/H7 -> 148.02632 | I32: =I6/I7 -> 163.39869 | J32: =J6/J7 -> 178.57143 | K32: =K6/K7 -> 193.54839 | L32: =L6/L7 -> 208.33333
A33: Taxa final Sessão → Venda | B33: 0.018843037 | C33: =C32/C16 -> 0.014835243 | D33: =D32/D16 -> 0.017979578 | F33: =F32/F16 -> 0.014835243 | G33: =G32/G16 -> 0.015816327 | H33: =H32/H16 -> 0.016879844 | I33: =I32/I16 -> 0.017999649 | J33: =J32/J16 -> 0.019040964 | K33: =K32/K16 -> 0.01973781 | L33: =L32/L16 -> 0.02044359
A34: Custo por sessão | B34: 0.92987149 | C34: =C4/C16 -> 0.31789807 | D34: =D4/D16 -> 0.55152314 | F34: =F4/F16 -> 0.63579614 | G34: =G4/G16 -> 0.59706635 | H34: =H4/H16 -> 0.57016362 | I34: =I4/I16 -> 0.55078927 | J34: =J4/J16 -> 0.533147 | K34: =K4/K16 -> 0.50989342 | L34: =L4/L16 -> 0.49064616
A35: Custo por pedido | B35: 44.060964 | C35: =C4/C30 -> 19.133571 | D35: =D4/D30 -> 27.427611 | F35: =F4/F30 -> 38.267143 | G35: =G4/G30 -> 33.71075 | H35: =H4/H30 -> 30.180444 | I35: =I4/I30 -> 27.3564 | J35: =J4/J30 -> 25.046 | K35: =K4/K30 -> 23.120833 | L35: =L4/L30 -> 21.48
A36: Custo por venda | B36: 49.34828 | C36: =C4/C32 -> 21.428571 | D36: =D4/D32 -> 30.674977 | F36: =F4/F32 -> 42.857143 | G36: =G4/G32 -> 37.75 | H36: =H4/H32 -> 33.777778 | I36: =I4/I32 -> 30.6 | J36: =J4/J32 -> 28 | K36: =K4/K32 -> 25.833333 | L36: =L4/L32 -> 24
A37: Receita recalculada | B37: 30112.98 | C37: =C32*C7 -> 70000 | D37: =D32*D7 -> 350000 | F37: =F32*F7 -> 35000 | G37: =G32*G7 -> 40000 | H37: =H32*H7 -> 45000 | I37: =I32*I7 -> 50000 | J37: =J32*J7 -> 55000 | K37: =K32*K7 -> 60000 | L37: =L32*L7 -> 65000
A38: Diferença vs. faturamento alvo | B38: 0 | C38: =ROUND(C37-C6,2) -> 0 | D38: =ROUND(D37-D6,2) -> 0 | F38: =ROUND(F37-F6,2) -> 0 | G38: =ROUND(G37-G6,2) -> 0 | H38: =ROUND(H37-H6,2) -> 0 | I38: =ROUND(I37-I6,2) -> 0 | J38: =ROUND(J37-J6,2) -> 0 | K38: =ROUND(K37-K6,2) -> 0 | L38: =ROUND(L37-L6,2) -> 0
A41: A coluna Breakeven da competência mostra o funil necessário para pagar Fee + mídia do mês, sem recuperar o carry over. Células amarelas são premissas do cenário; os volumes são calculados de trás para frente.

Sheet Realista
A1: Breakeven Realista — Dalpack
B2: Atual acumulado / funil maio | C2: Breakeven da competência | D2: Total projetado | F2: Mês 1 | G2: Mês 2 | H2: Mês 3 | I2: Mês 4 | J2: Mês 5 | K2: Mês 6 | L2: Mês 7
A3: Fee V4 | B3: 44000 | C3: ='Premissas'!F4 -> 5500 | D3: =SUM(F3:L3) -> 38500 | F3: ='Premissas'!F4 -> 5500 | G3: ='Premissas'!F4 -> 5500 | H3: ='Premissas'!F4 -> 5500 | I3: ='Premissas'!F4 -> 5500 | J3: ='Premissas'!F4 -> 5500 | K3: ='Premissas'!F4 -> 5500 | L3: ='Premissas'!F4 -> 5500
A4: Investimento de mídia | B4: 35163.169 | C4: =F4 -> 5000 | D4: =SUM(F4:L4) -> 59000 | F4: 5000 | G4: 5000 | H4: 8000 | I4: 8000 | J4: 11000 | K4: 11000 | L4: 11000
A5: Custo total | B5: 79163.169 | C5: =C3+C4 -> 10500 | D5: =SUM(F5:L5) -> 97500 | F5: =F3+F4 -> 10500 | G5: =G3+G4 -> 10500 | H5: =H3+H4 -> 13500 | I5: =I3+I4 -> 13500 | J5: =J3+J4 -> 16500 | K5: =K3+K4 -> 16500 | L5: =L3+L4 -> 16500
A6: Faturamento | B6: 214136.28 | C6: =C5/C8 -> 70000 | D6: =SUM(F6:L6) -> 983000 | F6: 55000 | G6: 75000 | H6: 121000 | I6: 146000 | J6: 187000 | K6: 197000 | L6: 202000
A7: Ticket médio | B7: 296.58765 | C7: =F7 -> 305 | D7: =D6/D32 -> 317.4514 | F7: 305 | G7: 308 | H7: 312 | I7: 315 | J7: 318 | K7: 322 | L7: 325
A8: Margem de contribuição | B8: 0.15 | C8: ='Premissas'!F7 -> 0.15 | D8: ='Premissas'!F7 -> 0.15 | F8: ='Premissas'!F7 -> 0.15 | G8: ='Premissas'!F7 -> 0.15 | H8: ='Premissas'!F7 -> 0.15 | I8: ='Premissas'!F7 -> 0.15 | J8: ='Premissas'!F7 -> 0.15 | K8: ='Premissas'!F7 -> 0.15 | L8: ='Premissas'!F7 -> 0.15
A9: Resultado MC | B9: 32120.442 | C9: =C6*C8 -> 10500 | D9: =D6*D8 -> 147450 | F9: =F6*F8 -> 8250 | G9: =G6*G8 -> 11250 | H9: =H6*H8 -> 18150 | I9: =I6*I8 -> 21900 | J9: =J6*J8 -> 28050 | K9: =K6*K8 -> 29550 | L9: =L6*L8 -> 30300
A10: Resultado líquido do mês | B10: -47042.727 | C10: =C9-C5 -> 0 | D10: =D9-D5 -> 49950 | F10: =F9-F5 -> -2250 | G10: =G9-G5 -> 750 | H10: =H9-H5 -> 4650 | I10: =I9-I5 -> 8400 | J10: =J9-J5 -> 11550 | K10: =K9-K5 -> 13050 | L10: =L9-L5 -> 13800
A11: Resultado líquido acumulado | B11: -47042.727 | C11: =C10 -> 0 | D11: =L11 -> 2907.27 | F11: =ROUND($B11+F10,2) -> -49292.73 | G11: =ROUND(F11+G10,2) -> -48542.73 | H11: =ROUND(G11+H10,2) -> -43892.73 | I11: =ROUND(H11+I10,2) -> -35492.73 | J11: =ROUND(I11+J10,2) -> -23942.73 | K11: =ROUND(J11+K10,2) -> -10892.73 | L11: =ROUND(K11+L10,2) -> 2907.27
A12: ROAS | B12: 6.0897889 | C12: =C6/C4 -> 14 | D12: =D6/D4 -> 16.661017 | F12: =F6/F4 -> 11 | G12: =G6/G4 -> 15 | H12: =H6/H4 -> 15.125 | I12: =I6/I4 -> 18.25 | J12: =J6/J4 -> 17 | K12: =K6/K4 -> 17.909091 | L12: =L6/L4 -> 18.363636
A13: Status | B13: Déficit a recuperar | C13: ZERA A COMPETÊNCIA | D13: =IF(D11>=0,"BREAKEVEN ATINGIDO","NÃO BREAKEVA") -> BREAKEVEN ATINGIDO | F13: =IF(F11>=0,"BREAKEVEN","EM RECUPERAÇÃO") -> EM RECUPERAÇÃO | G13: =IF(G11>=0,"BREAKEVEN","EM RECUPERAÇÃO") -> EM RECUPERAÇÃO | H13: =IF(H11>=0,"BREAKEVEN","EM RECUPERAÇÃO") -> EM RECUPERAÇÃO | I13: =IF(I11>=0,"BREAKEVEN","EM RECUPERAÇÃO") -> EM RECUPERAÇÃO | J13: =IF(J11>=0,"BREAKEVEN","EM RECUPERAÇÃO") -> EM RECUPERAÇÃO | K13: =IF(K11>=0,"BREAKEVEN","EM RECUPERAÇÃO") -> EM RECUPERAÇÃO | L13: =IF(L11>=0,"BREAKEVEN","EM RECUPERAÇÃO") -> BREAKEVEN
A15: Funil completo mês a mês
A16: Sessões | B16: 5307 | C16: =C18/C17 -> 11590.118 | D16: =SUM(F16:L16) -> 124779.66 | F16: =F18/F17 -> 9106.5211 | G16: =G18/G17 -> 11597.002 | H16: =H18/H17 -> 17236.512 | I16: =I18/I17 -> 19311.937 | J16: =J18/J17 -> 23060.339 | K16: =K18/K17 -> 22658.826 | L16: =L18/L17 -> 21808.52
A17: Taxa Sessão → View item | B17: 0.79574147 | C17: =F17 -> 0.8 | D17: =D18/D16 -> 0.86527579 | F17: 0.8 | G17: 0.82 | H17: 0.84 | I17: 0.86 | J17: 0.88 | K17: 0.89 | L17: 0.9
A18: View item | B18: 4223 | C18: =C20/C19 -> 9272.0942 | D18: =SUM(F18:L18) -> 107968.82 | F18: =F20/F19 -> 7285.2169 | G18: =G20/G19 -> 9509.542 | H18: =H20/H19 -> 14478.67 | I18: =I20/I19 -> 16608.266 | J18: =J20/J19 -> 20293.098 | K18: =K20/K19 -> 20166.356 | L18: =L20/L19 -> 19627.668
A19: Taxa View item → Add to cart | B19: 0.044281317 | C19: =F19 -> 0.22338235 | D19: =D20/D18 -> 0.21217745 | F19: 0.22338235 | G19: 0.2195122 | H19: 0.21568627 | I19: 0.2120383 | J19: 0.20855615 | K19: 0.20885658 | L19: 0.20915033
A20: Add to cart | B20: 187 | C20: =C22/C21 -> 2071.2222 | D20: =SUM(F20:L20) -> 22908.548 | F20: =F22/F21 -> 1627.3889 | G20: =G22/G21 -> 2087.4604 | H20: =H22/H21 -> 3122.8504 | I20: =I22/I21 -> 3521.5885 | J20: =J22/J21 -> 4232.2504 | K20: =K22/K21 -> 4211.876 | L20: =L22/L21 -> 4105.1331
A21: Taxa Add to cart → View cart | B21: 1 | C21: =F21 -> 0.85 | D21: =D22/D20 -> 0.85 | F21: 0.85 | G21: 0.85 | H21: 0.85 | I21: 0.85 | J21: 0.85 | K21: 0.85 | L21: 0.85
A22: View cart | B22: 306 | C22: =C24/C23 -> 1760.5389 | D22: =SUM(F22:L22) -> 19472.266 | F22: =F24/F23 -> 1383.2806 | G22: =G24/G23 -> 1774.3414 | H22: =H24/H23 -> 2654.4228 | I22: =I24/I23 -> 2993.3502 | J22: =J24/J23 -> 3597.4129 | K22: =K24/K23 -> 3580.0946 | L22: =L24/L23 -> 3489.3632
A23: Taxa View cart → Begin checkout | B23: 0.72875817 | C23: =F23 -> 0.897 | D23: =D24/D22 -> 0.89856483 | F23: 0.897 | G23: 0.897 | H23: 0.898 | I23: 0.898 | J23: 0.899 | K23: 0.899 | L23: 0.9
A24: Begin checkout | B24: 223 | C24: =C26/C25 -> 1579.2034 | D24: =SUM(F24:L24) -> 17497.093 | F24: =F26/F25 -> 1240.8027 | G24: =G26/G25 -> 1591.5842 | H24: =H26/H25 -> 2383.6717 | I24: =I26/I25 -> 2688.0285 | J24: =J26/J25 -> 3234.0742 | K24: =K26/K25 -> 3218.505 | L24: =L26/L25 -> 3140.4268
A25: Taxa Begin checkout → Add shipping info | B25: 1 | C25: =F25 -> 0.6846 | D25: =D26/D24 -> 0.72057435 | F25: 0.6846 | G25: 0.695 | H25: 0.705 | I25: 0.715 | J25: 0.725 | K25: 0.735 | L25: 0.745
A26: Add shipping info | B26: 495 | C26: =C28/C27 -> 1081.1226 | D26: =SUM(F26:L26) -> 12607.956 | F26: =F28/F27 -> 849.4535 | G26: =G28/G27 -> 1106.151 | H26: =H28/H27 -> 1680.4885 | I26: =I28/I27 -> 1921.9404 | J26: =J28/J27 -> 2344.7038 | K26: =K28/K27 -> 2365.6012 | L26: =L28/L27 -> 2339.618
A27: Taxa Add shipping info → Add payment info | B27: 0.66060606 | C27: =F27 -> 0.6606 | D27: =D28/D26 -> 0.70499847 | F27: 0.6606 | G27: 0.675 | H27: 0.69 | I27: 0.7 | J27: 0.71 | K27: 0.72 | L27: 0.73
A28: Add payment info | B28: 327 | C28: =C30/C29 -> 714.18962 | D28: =SUM(F28:L28) -> 8888.5899 | F28: =F30/F29 -> 561.14898 | G28: =G30/G29 -> 746.65194 | H28: =H30/H29 -> 1159.5371 | I28: =I30/I29 -> 1345.3583 | J28: =J30/J29 -> 1664.7397 | K28: =K30/K29 -> 1703.2329 | L28: =L30/L29 -> 1707.9211
A29: Taxa Add payment info → Pedido | B29: 0.34250765 | C29: =F29 -> 0.3599 | D29: =D30/D28 -> 0.38849576 | F29: 0.3599 | G29: 0.3648 | H29: 0.3737 | I29: 0.3845 | J29: 0.3938 | K29: 0.4 | L29: 0.4048
A30: Pedidos | B30: 112 | C30: =C32/C31 -> 257.03684 | D30: =SUM(F30:L30) -> 3453.1795 | F30: =F32/F31 -> 201.95752 | G30: =G32/G31 -> 272.37863 | H30: =H32/H31 -> 433.31901 | I30: =I32/I31 -> 517.29025 | J30: =J32/J31 -> 655.57449 | K30: =K32/K31 -> 681.29314 | L30: =L32/L31 -> 691.36648
A31: Taxa Pedido → Venda | B31: 0.89285714 | C31: =F31 -> 0.8929 | D31: =D32/D30 -> 0.89672053 | F31: 0.8929 | G31: 0.894 | H31: 0.895 | I31: 0.896 | J31: 0.897 | K31: 0.898 | L31: 0.899
A32: Vendas | B32: 100 | C32: =C6/C7 -> 229.5082 | D32: =SUM(F32:L32) -> 3096.537 | F32: =F6/F7 -> 180.32787 | G32: =G6/G7 -> 243.50649 | H32: =H6/H7 -> 387.82051 | I32: =I6/I7 -> 463.49206 | J32: =J6/J7 -> 588.05031 | K32: =K6/K7 -> 611.80124 | L32: =L6/L7 -> 621.53846
A33: Taxa final Sessão → Venda | B33: 0.018843037 | C33: =C32/C16 -> 0.019802059 | D33: =D32/D16 -> 0.02481604 | F33: =F32/F16 -> 0.019802059 | G33: =G32/G16 -> 0.020997365 | H33: =H32/H16 -> 0.022499942 | I33: =I32/I16 -> 0.024000289 | J33: =J32/J16 -> 0.025500506 | K33: =K32/K16 -> 0.027000571 | L33: =L32/L16 -> 0.028499801
A34: Custo por sessão | B34: 0.92987149 | C34: =C4/C16 -> 0.431402 | D34: =D4/D16 -> 0.47283348 | F34: =F4/F16 -> 0.54905709 | G34: =G4/G16 -> 0.4311459 | H34: =H4/H16 -> 0.46413103 | I34: =I4/I16 -> 0.41425156 | J34: =J4/J16 -> 0.47700947 | K34: =K4/K16 -> 0.48546204 | L34: =L4/L16 -> 0.50439003
A35: Custo por pedido | B35: 44.060964 | C35: =C4/C30 -> 19.452464 | D35: =D4/D30 -> 17.085703 | F35: =F4/F30 -> 24.757682 | G35: =G4/G30 -> 18.3568 | H35: =H4/H30 -> 18.462149 | I35: =I4/I30 -> 15.465205 | J35: =J4/J30 -> 16.779176 | K35: =K4/K30 -> 16.145766 | L35: =L4/L30 -> 15.91052
A36: Custo por venda | B36: 49.34828 | C36: =C4/C32 -> 21.785714 | D36: =D4/D32 -> 19.053543 | F36: =F4/F32 -> 27.727273 | G36: =G4/G32 -> 20.533333 | H36: =H4/H32 -> 20.628099 | I36: =I4/I32 -> 17.260274 | J36: =J4/J32 -> 18.705882 | K36: =K4/K32 -> 17.979695 | L36: =L4/L32 -> 17.69802
A37: Receita recalculada | B37: 30112.98 | C37: =C32*C7 -> 70000 | D37: =D32*D7 -> 983000 | F37: =F32*F7 -> 55000 | G37: =G32*G7 -> 75000 | H37: =H32*H7 -> 121000 | I37: =I32*I7 -> 146000 | J37: =J32*J7 -> 187000 | K37: =K32*K7 -> 197000 | L37: =L32*L7 -> 202000
A38: Diferença vs. faturamento alvo | B38: 0 | C38: =ROUND(C37-C6,2) -> 0 | D38: =ROUND(D37-D6,2) -> 0 | F38: =ROUND(F37-F6,2) -> 0 | G38: =ROUND(G37-G6,2) -> 0 | H38: =ROUND(H37-H6,2) -> 0 | I38: =ROUND(I37-I6,2) -> 0 | J38: =ROUND(J37-J6,2) -> 0 | K38: =ROUND(K37-K6,2) -> 0 | L38: =ROUND(L37-L6,2) -> 0
A41: A coluna Breakeven da competência mostra o funil necessário para pagar Fee + mídia do mês, sem recuperar o carry over. Células amarelas são premissas do cenário; os volumes são calculados de trás para frente.

Sheet Otimista
A1: Breakeven Otimista — Dalpack
B2: Atual acumulado / funil maio | C2: Breakeven da competência | D2: Total projetado | F2: Mês 1 | G2: Mês 2 | H2: Mês 3 | I2: Mês 4 | J2: Mês 5 | K2: Mês 6 | L2: Mês 7
A3: Fee V4 | B3: 44000 | C3: ='Premissas'!F4 -> 5500 | D3: =SUM(F3:L3) -> 38500 | F3: ='Premissas'!F4 -> 5500 | G3: ='Premissas'!F4 -> 5500 | H3: ='Premissas'!F4 -> 5500 | I3: ='Premissas'!F4 -> 5500 | J3: ='Premissas'!F4 -> 5500 | K3: ='Premissas'!F4 -> 5500 | L3: ='Premissas'!F4 -> 5500
A4: Investimento de mídia | B4: 35163.169 | C4: =F4 -> 5000 | D4: =SUM(F4:L4) -> 59000 | F4: 5000 | G4: 5000 | H4: 8000 | I4: 8000 | J4: 11000 | K4: 11000 | L4: 11000
A5: Custo total | B5: 79163.169 | C5: =C3+C4 -> 10500 | D5: =SUM(F5:L5) -> 97500 | F5: =F3+F4 -> 10500 | G5: =G3+G4 -> 10500 | H5: =H3+H4 -> 13500 | I5: =I3+I4 -> 13500 | J5: =J3+J4 -> 16500 | K5: =K3+K4 -> 16500 | L5: =L3+L4 -> 16500
A6: Faturamento | B6: 214136.28 | C6: =C5/C8 -> 70000 | D6: =SUM(F6:L6) -> 1152000 | F6: 65000 | G6: 90000 | H6: 144000 | I6: 169000 | J6: 213000 | K6: 228000 | L6: 243000
A7: Ticket médio | B7: 296.58765 | C7: =F7 -> 310 | D7: =D6/D32 -> 328.5656 | F7: 310 | G7: 315 | H7: 320 | I7: 325 | J7: 330 | K7: 335 | L7: 340
A8: Margem de contribuição | B8: 0.15 | C8: ='Premissas'!F7 -> 0.15 | D8: ='Premissas'!F7 -> 0.15 | F8: ='Premissas'!F7 -> 0.15 | G8: ='Premissas'!F7 -> 0.15 | H8: ='Premissas'!F7 -> 0.15 | I8: ='Premissas'!F7 -> 0.15 | J8: ='Premissas'!F7 -> 0.15 | K8: ='Premissas'!F7 -> 0.15 | L8: ='Premissas'!F7 -> 0.15
A9: Resultado MC | B9: 32120.442 | C9: =C6*C8 -> 10500 | D9: =D6*D8 -> 172800 | F9: =F6*F8 -> 9750 | G9: =G6*G8 -> 13500 | H9: =H6*H8 -> 21600 | I9: =I6*I8 -> 25350 | J9: =J6*J8 -> 31950 | K9: =K6*K8 -> 34200 | L9: =L6*L8 -> 36450
A10: Resultado líquido do mês | B10: -47042.727 | C10: =C9-C5 -> 0 | D10: =D9-D5 -> 75300 | F10: =F9-F5 -> -750 | G10: =G9-G5 -> 3000 | H10: =H9-H5 -> 8100 | I10: =I9-I5 -> 11850 | J10: =J9-J5 -> 15450 | K10: =K9-K5 -> 17700 | L10: =L9-L5 -> 19950
A11: Resultado líquido acumulado | B11: -47042.727 | C11: =C10 -> 0 | D11: =L11 -> 28257.27 | F11: =ROUND($B11+F10,2) -> -47792.73 | G11: =ROUND(F11+G10,2) -> -44792.73 | H11: =ROUND(G11+H10,2) -> -36692.73 | I11: =ROUND(H11+I10,2) -> -24842.73 | J11: =ROUND(I11+J10,2) -> -9392.73 | K11: =ROUND(J11+K10,2) -> 8307.27 | L11: =ROUND(K11+L10,2) -> 28257.27
A12: ROAS | B12: 6.0897889 | C12: =C6/C4 -> 14 | D12: =D6/D4 -> 19.525424 | F12: =F6/F4 -> 13 | G12: =G6/G4 -> 18 | H12: =H6/H4 -> 18 | I12: =I6/I4 -> 21.125 | J12: =J6/J4 -> 19.363636 | K12: =K6/K4 -> 20.727273 | L12: =L6/L4 -> 22.090909
A13: Status | B13: Déficit a recuperar | C13: ZERA A COMPETÊNCIA | D13: =IF(D11>=0,"BREAKEVEN ATINGIDO","NÃO BREAKEVA") -> BREAKEVEN ATINGIDO | F13: =IF(F11>=0,"BREAKEVEN","EM RECUPERAÇÃO") -> EM RECUPERAÇÃO | G13: =IF(G11>=0,"BREAKEVEN","EM RECUPERAÇÃO") -> EM RECUPERAÇÃO | H13: =IF(H11>=0,"BREAKEVEN","EM RECUPERAÇÃO") -> EM RECUPERAÇÃO | I13: =IF(I11>=0,"BREAKEVEN","EM RECUPERAÇÃO") -> EM RECUPERAÇÃO | J13: =IF(J11>=0,"BREAKEVEN","EM RECUPERAÇÃO") -> EM RECUPERAÇÃO | K13: =IF(K11>=0,"BREAKEVEN","EM RECUPERAÇÃO") -> BREAKEVEN | L13: =IF(L11>=0,"BREAKEVEN","EM RECUPERAÇÃO") -> BREAKEVEN
A15: Funil completo mês a mês
A16: Sessões | B16: 5307 | C16: =C18/C17 -> 10754.037 | D16: =SUM(F16:L16) -> 133839.85 | F16: =F18/F17 -> 9985.892 | G16: =G18/G17 -> 12697.561 | H16: =H18/H17 -> 18750.326 | I16: =I18/I17 -> 20390.688 | J16: =J18/J17 -> 23906.847 | K16: =K18/K17 -> 23882.618 | L16: =L18/L17 -> 24225.919
A17: Taxa Sessão → View item | B17: 0.79574147 | C17: =F17 -> 0.82 | D17: =D18/D16 -> 0.89049713 | F17: 0.82 | G17: 0.84 | H17: 0.86 | I17: 0.88 | J17: 0.9 | K17: 0.92 | L17: 0.94
A18: View item | B18: 4223 | C18: =C20/C19 -> 8818.3107 | D18: =SUM(F18:L18) -> 119184 | F18: =F20/F19 -> 8188.4314 | G18: =G20/G19 -> 10665.951 | H18: =H20/H19 -> 16125.281 | I18: =I20/I19 -> 17943.805 | J18: =J20/J19 -> 21516.163 | K18: =K20/K19 -> 21972.009 | L18: =L20/L19 -> 22772.364
A19: Taxa View item → Add to cart | B19: 0.044281317 | C19: =F19 -> 0.21202882 | D19: =D20/D18 -> 0.20465198 | F19: 0.21202882 | G19: 0.20968615 | H19: 0.20745243 | I19: 0.20532025 | J19: 0.20328283 | K19: 0.20256917 | L19: 0.2004352
A20: Add to cart | B20: 187 | C20: =C22/C21 -> 1869.7361 | D20: =SUM(F20:L20) -> 24391.242 | F20: =F22/F21 -> 1736.1835 | G20: =G22/G21 -> 2236.5022 | H20: =H22/H21 -> 3345.2287 | I20: =I22/I21 -> 3684.2266 | J20: =J22/J21 -> 4373.8664 | K20: =K22/K21 -> 4450.8516 | L20: =L22/L21 -> 4564.3834
A21: Taxa Add to cart → View cart | B21: 1 | C21: =F21 -> 0.88 | D21: =D22/D20 -> 0.88 | F21: 0.88 | G21: 0.88 | H21: 0.88 | I21: 0.88 | J21: 0.88 | K21: 0.88 | L21: 0.88
A22: View cart | B22: 306 | C22: =C24/C23 -> 1645.3677 | D22: =SUM(F22:L22) -> 21464.293 | F22: =F24/F23 -> 1527.8415 | G22: =G24/G23 -> 1968.122 | H22: =H24/H23 -> 2943.8012 | I22: =I24/I23 -> 3242.1194 | J22: =J24/J23 -> 3849.0024 | K22: =K24/K23 -> 3916.7494 | L22: =L24/L23 -> 4016.6574
A23: Taxa View cart → Begin checkout | B23: 0.72875817 | C23: =F23 -> 0.897 | D23: =D24/D22 -> 0.89899841 | F23: 0.897 | G23: 0.898 | H23: 0.898 | I23: 0.899 | J23: 0.899 | K23: 0.9 | L23: 0.9
A24: Begin checkout | B24: 223 | C24: =C26/C25 -> 1475.8949 | D24: =SUM(F24:L24) -> 19296.365 | F24: =F26/F25 -> 1370.4738 | G24: =G26/G25 -> 1767.3735 | H24: =H26/H25 -> 2643.5335 | I24: =I26/I25 -> 2914.6653 | J24: =J26/J25 -> 3460.2532 | K24: =K26/K25 -> 3525.0745 | L24: =L26/L25 -> 3614.9916
A25: Taxa Begin checkout → Add shipping info | B25: 1 | C25: =F25 -> 0.695 | D25: =D26/D24 -> 0.74028155 | F25: 0.695 | G25: 0.71 | H25: 0.725 | I25: 0.74 | J25: 0.75 | K25: 0.755 | L25: 0.76
A26: Add shipping info | B26: 495 | C26: =C28/C27 -> 1025.7469 | D26: =SUM(F26:L26) -> 14284.743 | F26: =F28/F27 -> 952.47929 | G26: =G28/G27 -> 1254.8352 | H26: =H28/H27 -> 1916.5618 | I26: =I28/I27 -> 2156.8523 | J26: =J28/J27 -> 2595.1899 | K26: =K28/K27 -> 2661.4312 | L26: =L28/L27 -> 2747.3936
A27: Taxa Add shipping info → Add payment info | B27: 0.66060606 | C27: =F27 -> 0.675 | D27: =D28/D26 -> 0.72174125 | F27: 0.675 | G27: 0.69 | H27: 0.705 | I27: 0.72 | J27: 0.73 | K27: 0.74 | L27: 0.74
A28: Add payment info | B28: 327 | C28: =C30/C29 -> 692.37918 | D28: =SUM(F28:L28) -> 10309.889 | F28: =F30/F29 -> 642.92352 | G28: =G30/G29 -> 865.83629 | H28: =H30/H29 -> 1351.1761 | I28: =I30/I29 -> 1552.9337 | J28: =J30/J29 -> 1894.4886 | K28: =K30/K29 -> 1969.4591 | L28: =L30/L29 -> 2033.0713
A29: Taxa Add payment info → Pedido | B29: 0.34250765 | C29: =F29 -> 0.3648 | D29: =D30/D28 -> 0.37882673 | F29: 0.3648 | G29: 0.3687 | H29: 0.3717 | I29: 0.3733 | J29: 0.3794 | K29: 0.3844 | L29: 0.3906
A30: Pedidos | B30: 112 | C30: =C32/C31 -> 252.57992 | D30: =SUM(F30:L30) -> 3905.6613 | F30: =F32/F31 -> 234.5385 | G30: =G32/G31 -> 319.23384 | H30: =H32/H31 -> 502.23214 | I30: =I32/I31 -> 579.71014 | J30: =J32/J31 -> 718.76898 | K30: =K32/K31 -> 757.06008 | L30: =L32/L31 -> 794.11765
A31: Taxa Pedido → Venda | B31: 0.89285714 | C31: =F31 -> 0.894 | D31: =D32/D30 -> 0.89770946 | F31: 0.894 | G31: 0.895 | H31: 0.896 | I31: 0.897 | J31: 0.898 | K31: 0.899 | L31: 0.9
A32: Vendas | B32: 100 | C32: =C6/C7 -> 225.80645 | D32: =SUM(F32:L32) -> 3506.1491 | F32: =F6/F7 -> 209.67742 | G32: =G6/G7 -> 285.71429 | H32: =H6/H7 -> 450 | I32: =I6/I7 -> 520 | J32: =J6/J7 -> 645.45455 | K32: =K6/K7 -> 680.59701 | L32: =L6/L7 -> 714.70588
A33: Taxa final Sessão → Venda | B33: 0.018843037 | C33: =C32/C16 -> 0.020997365 | D33: =D32/D16 -> 0.026196601 | F33: =F32/F16 -> 0.020997365 | G33: =G32/G16 -> 0.022501509 | H33: =H32/H16 -> 0.023999582 | I33: =I32/I16 -> 0.025501837 | J33: =J32/J16 -> 0.026998731 | K33: =K32/K16 -> 0.028497588 | L33: =L32/L16 -> 0.029501704
A34: Custo por sessão | B34: 0.92987149 | C34: =C4/C16 -> 0.46494166 | D34: =D4/D16 -> 0.44082535 | F34: =F4/F16 -> 0.5007064 | G34: =G4/G16 -> 0.39377641 | H34: =H4/H16 -> 0.42665924 | I34: =I4/I16 -> 0.39233595 | J34: =J4/J16 -> 0.46011922 | K34: =K4/K16 -> 0.46058601 | L34: =L4/L16 -> 0.45405914
A35: Custo por pedido | B35: 44.060964 | C35: =C4/C30 -> 19.795714 | D35: =D4/D30 -> 15.106276 | F35: =F4/F30 -> 21.318462 | G35: =G4/G30 -> 15.6625 | H35: =H4/H30 -> 15.928889 | I35: =I4/I30 -> 13.8 | J35: =J4/J30 -> 15.303944 | K35: =K4/K30 -> 14.52989 | L35: =L4/L30 -> 13.851852
A36: Custo por venda | B36: 49.34828 | C36: =C4/C32 -> 22.142857 | D36: =D4/D32 -> 16.827578 | F36: =F4/F32 -> 23.846154 | G36: =G4/G32 -> 17.5 | H36: =H4/H32 -> 17.777778 | I36: =I4/I32 -> 15.384615 | J36: =J4/J32 -> 17.042254 | K36: =K4/K32 -> 16.162281 | L36: =L4/L32 -> 15.390947
A37: Receita recalculada | B37: 30112.98 | C37: =C32*C7 -> 70000 | D37: =D32*D7 -> 1152000 | F37: =F32*F7 -> 65000 | G37: =G32*G7 -> 90000 | H37: =H32*H7 -> 144000 | I37: =I32*I7 -> 169000 | J37: =J32*J7 -> 213000 | K37: =K32*K7 -> 228000 | L37: =L32*L7 -> 243000
A38: Diferença vs. faturamento alvo | B38: 0 | C38: =ROUND(C37-C6,2) -> 0 | D38: =ROUND(D37-D6,2) -> 0 | F38: =ROUND(F37-F6,2) -> 0 | G38: =ROUND(G37-G6,2) -> 0 | H38: =ROUND(H37-H6,2) -> 0 | I38: =ROUND(I37-I6,2) -> 0 | J38: =ROUND(J37-J6,2) -> 0 | K38: =ROUND(K37-K6,2) -> 0 | L38: =ROUND(L37-L6,2) -> 0
A41: A coluna Breakeven da competência mostra o funil necessário para pagar Fee + mídia do mês, sem recuperar o carry over. Células amarelas são premissas do cenário; os volumes são calculados de trás para frente.

Sheet Funil Completo
A1: Funil Completo — Atual, Bench Mediana 8M e Projeção Gerencial
A3: Funil atual — Maio/2026 fechado | G3: Funil gerencial projetado — volumes necessários
A4: Etapa | B4: Volume atual | C4: Taxa atual | D4: Bench interno | E4: Validação | G4: Etapa | H4: Mês 1 | I4: Mês 2 | J4: Mês 3 | K4: Mês 4 | L4: Mês 5 | M4: Mês 6 | N4: Mês 7
A5: Sessões | B5: 5307 | C5: - | D5: - | E5: Base | G5: Faturamento | H5: ='Breakeven 7M'!E18 -> 61600 | I5: ='Breakeven 7M'!F18 -> 79800 | J5: ='Breakeven 7M'!G18 -> 98600 | K5: ='Breakeven 7M'!H18 -> 118000 | L5: ='Breakeven 7M'!I18 -> 132000 | M5: ='Breakeven 7M'!J18 -> 148800 | N5: ='Breakeven 7M'!K18 -> 164818.18
A6: Page view | B6: 15595 | C6: 2.9385717 | D6: - | E6: Múltiplas páginas por sessão | G6: Ticket médio | H6: ='Breakeven 7M'!E15 -> 296.58765 | I6: ='Breakeven 7M'!F15 -> 299.55352 | J6: ='Breakeven 7M'!G15 -> 302.54906 | K6: ='Breakeven 7M'!H15 -> 305.57455 | L6: ='Breakeven 7M'!I15 -> 308.63029 | M6: ='Breakeven 7M'!J15 -> 311.7166 | N6: ='Breakeven 7M'!K15 -> 314.83376
A7: View item | B7: 4223 | C7: 0.79574147 | D7: 0.9095749 | E7: Mediana de 8 meses | G7: Purchase | H7: ='Breakeven 7M'!E11 -> 207.69577 | I7: ='Breakeven 7M'!F11 -> 266.39647 | J7: ='Breakeven 7M'!G11 -> 325.89756 | K7: ='Breakeven 7M'!H11 -> 386.15782 | L7: ='Breakeven 7M'!I11 -> 427.69619 | M7: ='Breakeven 7M'!J11 -> 477.35668 | N7: ='Breakeven 7M'!K11 -> 523.5086
A8: Add to cart | B8: 187 | C8: 0.044281317 | D8: 0.16011846 | E8: Mediana de 8 meses | G8: Add to cart | H8: =H6/'Premissas'!F17 -> 369.89628 | I8: =I6/'Premissas'!G17 -> 474.43942 | J8: =J6/'Premissas'!H17 -> 580.40804 | K8: =K6/'Premissas'!I17 -> 687.72868 | L8: =L6/'Premissas'!J17 -> 761.70655 | M8: =M6/'Premissas'!K17 -> 850.14952 | N8: =N6/'Premissas'!L17 -> 932.34389
A9: View cart | B9: 306 | C9: 1.6363636 | D9: 0.61269841 | E9: Contagem atual não sequencial | G9: View item | H9: =H7/'Premissas'!F16 -> 8219.9173 | I9: =I7/'Premissas'!G16 -> 10094.456 | J9: =J7/'Premissas'!H16 -> 11845.062 | K9: =K7/'Premissas'!I16 -> 13484.876 | L9: =L7/'Premissas'!J16 -> 14371.822 | M9: =M7/'Premissas'!K16 -> 15457.264 | N9: =N7/'Premissas'!L16 -> 15937.502
A10: Begin checkout | B10: 223 | C10: 0.72875817 | D10: 0.42206552 | E10: Mediana de 8 meses | G10: Sessões | H10: =H8/'Premissas'!F15 -> 10274.897 | I10: =I8/'Premissas'!G15 -> 12310.312 | J10: =J8/'Premissas'!H15 -> 14101.264 | K10: =K8/'Premissas'!I15 -> 15680.089 | L10: =L8/'Premissas'!J15 -> 16331.615 | M10: =M8/'Premissas'!K15 -> 17367.712 | N10: =N8/'Premissas'!L15 -> 17708.336
A11: Add shipping info | B11: 495 | C11: 2.2197309 | D11: 0.9897541 | E11: Possível duplicidade atual | G11: Page views | H11: =H9*($B$6/$B$5) -> 30193.521 | I11: =I9*($B$6/$B$5) -> 36174.734 | J11: =J9*($B$6/$B$5) -> 41437.576 | K11: =K9*($B$6/$B$5) -> 46077.064 | L11: =L9*($B$6/$B$5) -> 47991.623 | M11: =M9*($B$6/$B$5) -> 51036.268 | N11: =N9*($B$6/$B$5) -> 52037.215
A12: Add payment info | B12: 327 | C12: 0.66060606 | D12: 0.68826729 | E12: Mediana de 8 meses | G12: Conversão final | H12: ='Breakeven 7M'!E13 -> 0.020213904 | I12: ='Breakeven 7M'!F13 -> 0.021640107 | J12: ='Breakeven 7M'!G13 -> 0.02311123 | K12: ='Breakeven 7M'!H13 -> 0.024627273 | L12: ='Breakeven 7M'!I13 -> 0.026188235 | M12: ='Breakeven 7M'!J13 -> 0.027485294 | N12: ='Breakeven 7M'!K13 -> 0.029562834
A13: Purchase | B13: 105 | C13: 0.32110092 | D13: 0.53823043 | E13: Mediana de 8 meses | G13: CPS necessário | H13: ='Breakeven 7M'!E6 -> 0.4866229 | I13: ='Breakeven 7M'!F6 -> 0.40616355 | J13: ='Breakeven 7M'!G6 -> 0.35457814 | K13: ='Breakeven 7M'!H6 -> 0.31887575 | L13: ='Breakeven 7M'!I6 -> 0.30615465 | M13: ='Breakeven 7M'!J6 -> 0.28789054 | N13: ='Breakeven 7M'!K6 -> 0.2823529
A14: Sessão → Purchase | B14: =B13/B5 -> 0.019785189 | C14: 0.019785189 | D14: 0.018426342 | E14: Bench: mediana dos 8 meses de LT | G14: Custo por compra | H14: ='Breakeven 7M'!E12 -> 24.073673 | I14: ='Breakeven 7M'!F12 -> 18.769018 | J14: ='Breakeven 7M'!G12 -> 15.342244 | K14: ='Breakeven 7M'!H12 -> 12.948074 | L14: ='Breakeven 7M'!I12 -> 11.690541 | M14: ='Breakeven 7M'!J12 -> 10.474348 | N14: ='Breakeven 7M'!K12 -> 9.5509414
A16: Atenção: View cart e Add shipping info apresentam contagem não sequencial no GA4. O bench usa a mediana mensal dos oito meses de LT, com taxas acima de 100% limitadas a 100%. A conversão final de 1,84% foi calculada diretamente por mês e não pela multiplicação das medianas das etapas. | G16: Taxas usadas na projeção
G17: Sessão → View item | H17: ='Premissas'!F15 -> 0.8 | I17: ='Premissas'!G15 -> 0.82 | J17: ='Premissas'!H15 -> 0.84 | K17: ='Premissas'!I15 -> 0.86 | L17: ='Premissas'!J15 -> 0.88 | M17: ='Premissas'!K15 -> 0.89 | N17: ='Premissas'!L15 -> 0.9
G18: View item → Add to cart | H18: ='Premissas'!F16 -> 0.045 | I18: ='Premissas'!G16 -> 0.047 | J18: ='Premissas'!H16 -> 0.049 | K18: ='Premissas'!I16 -> 0.051 | L18: ='Premissas'!J16 -> 0.053 | M18: ='Premissas'!K16 -> 0.055 | N18: ='Premissas'!L16 -> 0.0585
G19: Add to cart → Purchase | H19: ='Premissas'!F17 -> 0.56149733 | I19: ='Premissas'!G17 -> 0.56149733 | J19: ='Premissas'!H17 -> 0.56149733 | K19: ='Premissas'!I17 -> 0.56149733 | L19: ='Premissas'!J17 -> 0.56149733 | M19: ='Premissas'!K17 -> 0.56149733 | N19: ='Premissas'!L17 -> 0.56149733
G21: O funil gerencial preserva as etapas confiáveis do tracking. As etapas detalhadas permanecem no bloco da esquerda para orientar a auditoria técnica do GTM/GA4.

Sheet Premissas
A1: Premissas — Breakeven E-commerce Dalpack
A3: Cenário atual | E3: Premissas futuras — células amarelas são editáveis
A4: Cliente | B4: Dalpack | C4: Editável | E4: Fee mensal | F4: 5500
A5: Período atual | B5: Nov/2025 a Jun/2026 | C5: Meses com Fee V4 | E5: Mídia mensal | F5: 5000
A6: Meses com fee | B6: =COUNTA('Dados Fonte'!A4:A11) -> 8 | C6: Calculado a partir dos dados fonte | E6: Meses para recuperar | F6: 7
A7: Fee acumulado | B7: ='Dados Fonte'!B12 -> 44000 | C7: Linha 6 | E7: Margem | F7: 0.15
A8: Investimento acumulado | B8: ='Dados Fonte'!C12 -> 35163.169 | C8: Linha 9 | E8: Breakeven mensal | F8: =(F4+F5)/F7 -> 70000
A9: Custo acumulado | B9: =B7+B8 -> 79163.169 | C9: Fee + investimento | E9: Custo futuro | F9: =(F4+F5)*F6 -> 73500
A10: Faturamento acumulado | B10: ='Dados Fonte'!G12 -> 214136.28 | C10: Linha 28 | E10: Receita futura necessária | F10: =(ABS(B17)+F9)/F7 -> 803618.18
A11: Sessões acumuladas | B11: ='Dados Fonte'!D12 -> 44452 | C11: Meses com fee
A12: Pedidos acumulados | B12: ='Dados Fonte'!E12 -> 867 | C12: Meses com fee | E12: Curva mensal editável
A13: Vendas acumuladas | B13: ='Dados Fonte'!F12 -> 722 | C13: Meses com fee | E13: Premissa | F13: Mês 1 | G13: Mês 2 | H13: Mês 3 | I13: Mês 4 | J13: Mês 5 | K13: Mês 6 | L13: Mês 7
A14: Ticket médio | B14: =B10/B13 -> 296.58765 | C14: Faturamento ÷ vendas | E14: Faturamento alvo | F14: 61600 | G14: 79800 | H14: 98600 | I14: 118000 | J14: 132000 | K14: 148800 | L14: =F10-SUM(F14:K14) -> 164818.18
A15: Margem de contribuição | B15: 0.15 | C15: Premissa editável | E15: View item / sessão | F15: 0.8 | G15: 0.82 | H15: 0.84 | I15: 0.86 | J15: 0.88 | K15: 0.89 | L15: 0.9
A16: Resultado MC | B16: =B10*B15 -> 32120.442 | C16: Faturamento × margem | E16: Add to cart / view item | F16: 0.045 | G16: 0.047 | H16: 0.049 | I16: 0.051 | J16: 0.053 | K16: 0.055 | L16: 0.0585
A17: Resultado líquido | B17: =B16-B9 -> -47042.727 | C17: MC - custo | E17: Purchase / add to cart | F17: 0.56149733 | G17: 0.56149733 | H17: 0.56149733 | I17: 0.56149733 | J17: 0.56149733 | K17: 0.56149733 | L17: 0.56149733
E18: Aprovação pedido → venda | F18: 0.83275663 | G18: 0.83563053 | H18: 0.83850442 | I18: 0.84137832 | J18: 0.84425221 | K18: 0.84712611 | L18: 0.85
A20: Como usar: altere somente as células amarelas. A projeção, o saldo acumulado, os volumes do funil e os indicadores são recalculados automaticamente. O Mês 7 equilibra o faturamento necessário para zerar o projeto no prazo definido.

Sheet Dados Fonte
A1: Dados Fonte — Dalpack
A3: Mês | B3: Fee V4 | C3: Investimento | D3: Sessões | E3: Pedidos | F3: Vendas | G3: Faturamento | H3: Período válido
A4: Nov/25 | B4: 5500 | C4: 3635.07 | D4: 6645 | E4: 128 | F4: 104 | G4: 27215.28 | H4: Sim — mês com fee
A5: Dez/25 | B5: 5500 | C5: 4325.19 | D5: 5415 | E5: 128 | F5: 107 | G5: 28908.6 | H5: Sim — mês com fee
A6: Jan/26 | B6: 5500 | C6: 4503.5268 | D6: 5735 | E6: 117 | F6: 96 | G6: 35238.68 | H6: Sim — mês com fee
A7: Fev/26 | B7: 5500 | C7: 5047.6525 | D7: 7340 | E7: 87 | F7: 71 | G7: 18132.38 | H7: Sim — mês com fee
A8: Mar/26 | B8: 5500 | C8: 4963.8563 | D8: 6323 | E8: 123 | F8: 101 | G8: 30923.47 | H8: Sim — mês com fee
A9: Abr/26 | B9: 5500 | C9: 4958.2038 | D9: 4878 | E9: 116 | F9: 98 | G9: 30903.38 | H9: Sim — mês com fee
A10: Mai/26 | B10: 5500 | C10: 4934.828 | D10: 5307 | E10: 112 | F10: 100 | G10: 30112.98 | H10: Sim — mês com fee
A11: Jun/26 | B11: 5500 | C11: 2794.842 | D11: 2809 | E11: 56 | F11: 45 | G11: 12701.51 | H11: Sim — mês com fee
A12: TOTAL | B12: =SUM(B4:B11) -> 44000 | C12: =SUM(C4:C11) -> 35163.169 | D12: =SUM(D4:D11) -> 44452 | E12: =SUM(E4:E11) -> 867 | F12: =SUM(F4:F11) -> 722 | G12: =SUM(G4:G11) -> 214136.28 | H12: Somente meses com Fee V4
A15: Funil atual — Maio/2026 fechado
A16: Etapa | B16: Volume | C16: Taxa atual | D16: Bench interno | E16: Status | F16: Fonte
A17: Sessões | B17: 5307 | C17: - | D17: - | E17: Base | F17: GA4 / Growth Pack
A18: Page view | B18: 15595 | C18: 2.9385717 | D18: - | E18: Múltiplas páginas por sessão | F18: GA4 / Growth Pack
A19: View item | B19: 4223 | C19: 0.79574147 | D19: 0.9095749 | E19: Mediana de 8 meses | F19: GA4 / Growth Pack
A20: Add to cart | B20: 187 | C20: 0.044281317 | D20: 0.16011846 | E20: Mediana de 8 meses | F20: GA4 / Growth Pack
A21: View cart | B21: 306 | C21: 1.6363636 | D21: 0.61269841 | E21: Contagem atual não sequencial | F21: GA4 / Growth Pack
A22: Begin checkout | B22: 223 | C22: 0.72875817 | D22: 0.42206552 | E22: Mediana de 8 meses | F22: GA4 / Growth Pack
A23: Add shipping info | B23: 495 | C23: 2.2197309 | D23: 0.9897541 | E23: Possível duplicidade atual | F23: GA4 / Growth Pack
A24: Add payment info | B24: 327 | C24: 0.66060606 | D24: 0.68826729 | E24: Mediana de 8 meses | F24: GA4 / Growth Pack
A25: Purchase | B25: 105 | C25: 0.32110092 | D25: 0.53823043 | E25: Mediana de 8 meses | F25: GA4 / Growth Pack
A27: Sessão → Purchase | B27: =B25/B17 -> 0.019785189 | C27: 0.019785189 | D27: 0.018426342 | E27: Bench: mediana 8M | F27: Nov/2025 a Jun/2026
A29: Fonte: Growth Pack Dalpack. O cenário financeiro usa Fee V4 da linha 6, investimento da linha 9 e faturamento da linha 28, apenas nos meses em que há fee preenchido.
A34: Base mensal do bench — volumes de eventos
A35: Mês | B35: Sessões | C35: View item | D35: Add to cart | E35: View cart | F35: Begin checkout | G35: Add shipping | H35: Add payment | I35: Purchase
A36: Nov/25 | B36: 6645 | C36: 5692 | D36: 776 | E36: 998 | F36: 222 | G36: 260 | H36: 178 | I36: 107
A37: Dez/25 | B37: 5415 | C37: 4989 | D37: 945 | E37: 591 | F37: 244 | G37: 239 | H37: 187 | I37: 110
A38: Jan/26 | B38: 6445 | C38: 6030 | D38: 946 | E38: 554 | F38: 215 | G38: 207 | H38: 148 | I38: 110
A39: Fev/26 | B39: 7340 | C39: 6590 | D39: 920 | E39: 620 | F39: 212 | G39: 198 | H39: 137 | I39: 68
A40: Mar/26 | B40: 6323 | C40: 5938 | D40: 970 | E40: 582 | F40: 251 | G40: 239 | H40: 181 | I40: 105
A41: Abr/26 | B41: 4878 | C41: 3994 | D41: 919 | E41: 309 | F41: 222 | G41: 552 | H41: 325 | I41: 107
A42: Mai/26 | B42: 5307 | C42: 4223 | D42: 187 | E42: 306 | F42: 223 | G42: 495 | H42: 327 | I42: 105
A43: Jun/26 | B43: 2809 | C43: 2628 | D43: 583 | E43: 197 | F43: 167 | G43: 367 | H43: 249 | I43: 80
A46: Bench interno — taxas mensais e mediana dos 8 meses
A47: Mês | B47: Sessão → View item | C47: View item → Add cart | D47: Add cart → View cart | E47: View cart → Checkout | F47: Checkout → Shipping | G47: Shipping → Payment | H47: Payment → Purchase | I47: Sessão → Purchase
A48: Nov/25 | B48: =MIN(1,C36/B36) -> 0.8565839 | C48: =MIN(1,D36/C36) -> 0.13633169 | D48: =MIN(1,E36/D36) -> 1 | E48: =MIN(1,F36/E36) -> 0.22244489 | F48: =MIN(1,G36/F36) -> 1 | G48: =MIN(1,H36/G36) -> 0.68461538 | H48: =MIN(1,I36/H36) -> 0.6011236 | I48: =MIN(1,I36/B36) -> 0.016102333
A49: Dez/25 | B49: =MIN(1,C37/B37) -> 0.92132964 | C49: =MIN(1,D37/C37) -> 0.18941672 | D49: =MIN(1,E37/D37) -> 0.62539683 | E49: =MIN(1,F37/E37) -> 0.41285956 | F49: =MIN(1,G37/F37) -> 0.9795082 | G49: =MIN(1,H37/G37) -> 0.78242678 | H49: =MIN(1,I37/H37) -> 0.58823529 | I49: =MIN(1,I37/B37) -> 0.020313943
A50: Jan/26 | B50: =MIN(1,C38/B38) -> 0.935609 | C50: =MIN(1,D38/C38) -> 0.15688226 | D50: =MIN(1,E38/D38) -> 0.58562368 | E50: =MIN(1,F38/E38) -> 0.38808664 | F50: =MIN(1,G38/F38) -> 0.9627907 | G50: =MIN(1,H38/G38) -> 0.71497585 | H50: =MIN(1,I38/H38) -> 0.74324324 | I50: =MIN(1,I38/B38) -> 0.017067494
A51: Fev/26 | B51: =MIN(1,C39/B39) -> 0.89782016 | C51: =MIN(1,D39/C39) -> 0.13960546 | D51: =MIN(1,E39/D39) -> 0.67391304 | E51: =MIN(1,F39/E39) -> 0.34193548 | F51: =MIN(1,G39/F39) -> 0.93396226 | G51: =MIN(1,H39/G39) -> 0.69191919 | H51: =MIN(1,I39/H39) -> 0.49635036 | I51: =MIN(1,I39/B39) -> 0.0092643052
...
